<?xml version="1.0" encoding="UTF-8"?>
<!-- Generated by org.testng.reporters.JUnitReportReporter -->
<testsuite hostname="SHA-LRI-PC-264" name="trainTestNG.TestFunc" tests="4" failures="1" timestamp="16 Aug 2018 07:20:27 GMT" time="0.005" errors="1">
  <testcase name="testMethod2" time="0.000" classname="trainTestNG.TestFunc"/>
  <testcase name="testMethod3" time="0.001" classname="trainTestNG.TestFunc"/>
  <testcase name="testMethod4" time="0.000" classname="trainTestNG.TestFunc">
    <error type="java.lang.Throwable" message="Method TestFunc.testMethod4()[pri:0, instance:trainTestNG.TestFunc@233c0b17] depends on not successfully finished methods">
      <![CDATA[java.lang.Throwable: Method TestFunc.testMethod4()[pri:0, instance:trainTestNG.TestFunc@233c0b17] depends on not successfully finished methods
	at org.testng.internal.Invoker.invokeTestMethods(Invoker.java:1037)
	at org.testng.internal.TestMethodWorker.invokeTestMethods(TestMethodWorker.java:129)
	at org.testng.internal.TestMethodWorker.run(TestMethodWorker.java:112)
	at org.testng.TestRunner.privateRun(TestRunner.java:782)
	at org.testng.TestRunner.run(TestRunner.java:632)
	at org.testng.SuiteRunner.runTest(SuiteRunner.java:366)
	at org.testng.SuiteRunner.runSequentially(SuiteRunner.java:361)
	at org.testng.SuiteRunner.privateRun(SuiteRunner.java:319)
	at org.testng.SuiteRunner.run(SuiteRunner.java:268)
	at org.testng.SuiteRunnerWorker.runSuite(SuiteRunnerWorker.java:52)
	at org.testng.SuiteRunnerWorker.run(SuiteRunnerWorker.java:86)
	at org.testng.TestNG.runSuitesSequentially(TestNG.java:1246)
	at org.testng.TestNG.runSuitesLocally(TestNG.java:1171)
	at org.testng.TestNG.run(TestNG.java:1066)
	at org.testng.TestNG.privateMain(TestNG.java:1387)
	at org.testng.TestNG.main(TestNG.java:1356)
]]>
    </error>
  </testcase> <!-- testMethod4 -->
  <testcase name="testMethod1" time="0.004" classname="trainTestNG.TestFunc">
    <failure type="java.lang.AssertionError" message="expected [true] but found [false]">
      <![CDATA[java.lang.AssertionError: expected [true] but found [false]
	at org.testng.Assert.fail(Assert.java:94)
	at org.testng.Assert.failNotEquals(Assert.java:496)
	at org.testng.Assert.assertTrue(Assert.java:42)
	at org.testng.Assert.assertTrue(Assert.java:52)
	at trainTestNG.TestFunc.testMethod1(TestFunc.java:31)
	at sun.reflect.NativeMethodAccessorImpl.invoke0(Native Method)
	at sun.reflect.NativeMethodAccessorImpl.invoke(Unknown Source)
	at sun.reflect.DelegatingMethodAccessorImpl.invoke(Unknown Source)
	at java.lang.reflect.Method.invoke(Unknown Source)
	at org.testng.internal.MethodInvocationHelper.invokeMethod(MethodInvocationHelper.java:86)
	at org.testng.internal.Invoker.invokeMethod(Invoker.java:643)
	at org.testng.internal.Invoker.invokeTestMethod(Invoker.java:820)
	at org.testng.internal.Invoker.invokeTestMethods(Invoker.java:1128)
	at org.testng.internal.TestMethodWorker.invokeTestMethods(TestMethodWorker.java:129)
	at org.testng.internal.TestMethodWorker.run(TestMethodWorker.java:112)
	at org.testng.TestRunner.privateRun(TestRunner.java:782)
	at org.testng.TestRunner.run(TestRunner.java:632)
	at org.testng.SuiteRunner.runTest(SuiteRunner.java:366)
	at org.testng.SuiteRunner.runSequentially(SuiteRunner.java:361)
	at org.testng.SuiteRunner.privateRun(SuiteRunner.java:319)
	at org.testng.SuiteRunner.run(SuiteRunner.java:268)
	at org.testng.SuiteRunnerWorker.runSuite(SuiteRunnerWorker.java:52)
	at org.testng.SuiteRunnerWorker.run(SuiteRunnerWorker.java:86)
	at org.testng.TestNG.runSuitesSequentially(TestNG.java:1246)
	at org.testng.TestNG.runSuitesLocally(TestNG.java:1171)
	at org.testng.TestNG.run(TestNG.java:1066)
	at org.testng.TestNG.privateMain(TestNG.java:1387)
	at org.testng.TestNG.main(TestNG.java:1356)
]]>
    </failure>
  </testcase> <!-- testMethod1 -->
</testsuite> <!-- trainTestNG.TestFunc -->
